<mujoco model="X5A">
  <option timestep="0.01" gravity="0 0 0"/>
  <default>
    <default class="robot">
      <default class="motor">
        <joint />
        <motor />
      </default>
      <default class="visual">
        <geom material="visualgeom" contype="0" conaffinity="0" group="2" />
      </default>
      <default class="collision">
        <geom material="collision_material" condim="3" contype="0" conaffinity="1" priority="1" group="1" solref="0.005 1" solimp="0.99 0.999 1e-05" friction="1 0.01 0.01" />
      </default>
    </default>
  </default>

  <compiler angle="radian" />

  <asset>
    <material name="black" rgba="0 0 0 1" />
    <material name="white" rgba="1 1 1 1" />
    <material name="default_material" rgba="0.7 0.7 0.7 1" />
    <material name="collision_material" rgba="1.0 0.28 0.1 0.9" />
    <mesh name="base_link.STL" file="meshes/base_link.STL" />
    <mesh name="link1.STL" file="meshes/link1.STL" />
    <mesh name="link2.STL" file="meshes/link2.STL" />
    <mesh name="link3.STL" file="meshes/link3.STL" />
    <mesh name="link4.STL" file="meshes/link4.STL" />
    <mesh name="link5.STL" file="meshes/link5.STL" />
    <mesh name="link6.STL" file="meshes/link6.STL" />
    <mesh name="camera_base.obj" file="meshes/camera_base.obj" />
    <mesh name="camera.obj" file="meshes/camera.obj" />
    <mesh name="link7.STL" file="meshes/link7.STL" />
    <mesh name="link8.STL" file="meshes/link8.STL" />
  </asset>

  <worldbody>
    <body name="base_link" pos="0.00000000 0.00000000 0.00000000" quat="1 0 0 0" childclass="robot">
      <freejoint name="floating_base" />
      <geom name="base_link_collision" pos="0 0 0" quat="1.0 0.0 0.0 0.0" type="mesh" mesh="base_link.STL" class="collision" />
      <geom name="base_link_visual" pos="0 0 0" quat="1.0 0.0 0.0 0.0" material="black" type="mesh" mesh="base_link.STL" class="visual" />
      <body name="link1" pos="0 0 0.0605" quat="1.0 0.0 0.0 0.0">
        <joint name="joint1" type="hinge" ref="0.0" class="motor" range="-10 10" axis="0 0 1" />
        <inertial pos="0.0054231 -0.0080289 0.017086" quat="1.0 0.0 0.0 0.0" mass="0.066982" diaginertia="8e-05 3e-05 8e-05" />
        <geom name="link1_collision" pos="0 0 0" quat="1.0 0.0 0.0 0.0" type="mesh" mesh="link1.STL" class="collision" />
        <geom name="link1_visual" pos="0 0 0" quat="1.0 0.0 0.0 0.0" material="black" type="mesh" mesh="link1.STL" class="visual" />
        <body name="link2" pos="0.02 0 0.04" quat="1.0 0.0 0.0 0.0">
          <joint name="joint2" type="hinge" ref="0.0" class="motor" range="-10 10" axis="0 1 0" />
          <inertial pos="-0.13237 0.0020852 0.00010549" quat="1.0 0.0 0.0 0.0" mass="1.0795" diaginertia="0.00051 0.01599 0.01605" />
          <geom name="link2_collision" pos="0 0 0" quat="1.0 0.0 0.0 0.0" type="mesh" mesh="link2.STL" class="collision" />
          <geom name="link2_visual" pos="0 0 0" quat="1.0 0.0 0.0 0.0" material="black" type="mesh" mesh="link2.STL" class="visual" />
          <body name="link3" pos="-0.264 0 0" quat="-3.673205103346574e-06 0.9999999999932537 0.0 -0.0">
            <joint name="joint3" type="hinge" ref="0.0" class="motor" range="-10 10" axis="0 1 0" />
            <inertial pos="0.18531 0.00068376 -0.051638" quat="1.0 0.0 0.0 0.0" mass="0.54534" diaginertia="0.00036 0.00423 0.0042" />
            <geom name="link3_collision" pos="0 0 0" quat="1.0 0.0 0.0 0.0" type="mesh" mesh="link3.STL" class="collision" />
            <geom name="link3_visual" pos="0 0 0" quat="1.0 0.0 0.0 0.0" material="white" type="mesh" mesh="link3.STL" class="visual" />
            <body name="link4" pos="0.245 0 -0.056" quat="1.0 0.0 0.0 0.0">
              <joint name="joint4" type="hinge" ref="0.0" class="motor" range="-10 10" axis="0 1 0" />
              <inertial pos="0.040231 0.0044807 -0.035335" quat="1.0 0.0 0.0 0.0" mass="0.11714" diaginertia="0.00019 0.00023 0.00014" />
              <geom name="link4_collision" pos="0 0 0" quat="1.0 0.0 0.0 0.0" type="mesh" mesh="link4.STL" class="collision" />
              <geom name="link4_visual" pos="0 0 0" quat="1.0 0.0 0.0 0.0" material="black" type="mesh" mesh="link4.STL" class="visual" />
              <body name="link5" pos="0.06775 0.0005 -0.0865" quat="1.0 0.0 0.0 0.0">
                <joint name="joint5" type="hinge" ref="0.0" class="motor" range="-10 10" axis="0 0 1" />
                <inertial pos="0.003612 -1.5455E-05 0.055214" quat="1.0 0.0 0.0 0.0" mass="0.63488" diaginertia="0.00083 0.00082 0.00026" />
                <geom name="link5_collision" pos="0 0 0" quat="1.0 0.0 0.0 0.0" type="mesh" mesh="link5.STL" class="collision" />
                <geom name="link5_visual" pos="0 0 0" quat="1.0 0.0 0.0 0.0" material="black" type="mesh" mesh="link5.STL" class="visual" />
                <body name="link6" pos="0.02895 0 0.0865" quat="-3.673205103346574e-06 -0.9999999999932537 -0.0 0.0">
                  <joint name="joint6" type="hinge" ref="0.0" class="motor" range="-3.14 3.14" axis="1 0 0" />
                  <inertial pos="0.041697 2.4368E-05 0.00014464" quat="1.0 0.0 0.0 0.0" mass="0.44089" diaginertia="0.00038 0.00028 0.0005" />
                  <geom name="link6_collision" pos="0 0 0" quat="1.0 0.0 0.0 0.0" type="mesh" mesh="link6.STL" class="collision" />
                  <geom name="link6_visual" pos="0 0 0" quat="1.0 0.0 0.0 0.0" material="black" type="mesh" mesh="link6.STL" class="visual" />
                  <body name="camera_base" pos="0.057 0 0" quat="-3.673205103346574e-06 0.0 -0.0 -0.9999999999932537">
                    <geom name="camera_base_visual" pos="0 0 0.0" quat="1.0 0.0 0.0 0.0" material="default_material" type="mesh" mesh="camera_base.obj" class="visual" />
                    <body name="camera" pos="-0.0275 0.0 0.05" quat="6.030190156192642e-17 -0.17366499303759564 1.0633913892371944e-17 0.984804787860646">
                      <geom name="camera_visual" pos="0.0 0.0 -0.0" quat="0.7071067811865476 0.0 0.0 -0.7071067811865476" material="default_material" type="mesh" mesh="camera.obj" class="visual" />
                    </body>
                  </body>
                  <body name="link7" pos="0.08657 0.024896 -0.0002436" quat="1.0 0.0 0.0 0.0">
                    <joint name="joint7" type="slide" ref="0.0" class="motor" range="0 0.044" axis="0 1 0" />
                    <inertial pos="-0.00035522 -0.007827 -0.0029883" quat="1.0 0.0 0.0 0.0" mass="0.064798" diaginertia="2e-05 3e-05 3e-05" />
                    <geom name="link7_collision" pos="0 0 0" quat="1.0 0.0 0.0 0.0" type="mesh" mesh="link7.STL" class="collision" />
                    <geom name="link7_visual" pos="0 0 0" quat="1.0 0.0 0.0 0.0" material="black" type="mesh" mesh="link7.STL" class="visual" />
                  </body>
                  <body name="link8" pos="0.08657 -0.0249 -0.00024366" quat="1.0 0.0 0.0 0.0">
                    <joint name="joint8" type="slide" ref="0.0" class="motor" range="0 0.044" axis="0 -1 0" />
                    <inertial pos="-0.00035522 0.0078277 0.0024201" quat="1.0 0.0 0.0 0.0" mass="0.064798" diaginertia="2e-05 3e-05 3e-05" />
                    <geom name="link8_collision" pos="0 0 0" quat="1.0 0.0 0.0 0.0" type="mesh" mesh="link8.STL" class="collision" />
                    <geom name="link8_visual" pos="0 0 0" quat="1.0 0.0 0.0 0.0" material="black" type="mesh" mesh="link8.STL" class="visual" />
                  </body>
                </body>
              </body>
            </body>
          </body>
        </body>
      </body>
      <site name="base_link_site" pos="0 0 0" quat="1 0 0 0" />
      <camera name="front_camera" mode="track" fovy="90.0" quat="4.329637285359678e-17 4.329637285359677e-17 0.7071067811865475 0.7071067811865476" pos="0.0 2.0 0.5" />
      <camera name="side_camera" mode="track" fovy="90.0" quat="-0.5 -0.4999999999999999 0.5 0.5000000000000001" pos="-2.0 0.0 0.5" />
    </body>
  </worldbody>

  <actuator>
    <motor name="joint1_ctrl" joint="joint1" class="motor" />
    <motor name="joint2_ctrl" joint="joint2" class="motor" />
    <motor name="joint3_ctrl" joint="joint3" class="motor" />
    <motor name="joint4_ctrl" joint="joint4" class="motor" />
    <motor name="joint5_ctrl" joint="joint5" class="motor" />
    <motor name="joint6_ctrl" joint="joint6" class="motor" />
    <motor name="joint7_ctrl" joint="joint7" class="motor" />
    <motor name="joint8_ctrl" joint="joint8" class="motor" />
  </actuator>

  <contact>
    <exclude body1="base_link" body2="link1" />
    <exclude body1="link1" body2="link2" />
    <exclude body1="link2" body2="link3" />
    <exclude body1="link3" body2="link4" />
    <exclude body1="link4" body2="link5" />
    <exclude body1="link5" body2="link6" />
    <exclude body1="link6" body2="link7" />
    <exclude body1="link6" body2="link8" />
  </contact>

  <sensor>
    <framepos name="base_link_site_pos" objtype="site" objname="base_link_site" />
    <framequat name="base_link_site_quat" objtype="site" objname="base_link_site" />
    <framelinvel name="base_link_site_linvel" objtype="site" objname="base_link_site" />
    <frameangvel name="base_link_site_angvel" objtype="site" objname="base_link_site" />
    <velocimeter name="base_link_site_vel" site="base_link_site" />
  </sensor>
</mujoco>